<?xml version="1.0"?>
<robot name="omnidirectional_four-wheeled_robot">
	<link name="base_link"/>
	<link name="body_link">
		<visual>
			<geometry>
				<box size="0.750 0.750 0.250"/>
			</geometry>
			<material name="White">
				<color rgba="1. 1. 1. 1."/>
			</material>
		</visual>

		<collision>
			<geometry>
				<box size="0.750 0.750 0.250"/>
			</geometry>
		</collision>

		<inertial>
			<origin xyz="0 0 0"/>
			<mass value="0.500"/>
			<inertia ixx="0.0020833333" ixy="0" ixz="0" 
					  iyy="0.0070833333" iyz="0"
					  izz="0.0083333333"/>
		</inertial>
	</link>

	<link name="FRwheel_link1">
		<visual>
			<geometry>
				<cylinder radius="0.2" length="0.1"/>
			</geometry>
			<material name="Black">
				<color rgba="0. 0. 0. 1."/>
			</material>
		</visual>
		<collision>
			<geometry>
				<cylinder radius="0.2" length="0.1"/>
			</geometry>
		</collision>
		<inertial>
			<origin xyz="0. 0. 0."/>
			<mass value="2."/>
			<inertia ixx="0.0020833333" ixy="0." ixz="0." 
					  iyy="0.0070833333" iyz="0."
					  izz="0.0083333333"/>
		</inertial>
	</link>

	<link name="FRwheel_link2">
		<visual>
			<geometry>
				<cylinder radius="0.2" length="0.1"/>
			</geometry>
			<material name="Black">
				<color rgba="0. 0. 0. 1."/>
			</material>
		</visual>
		<collision>
			<geometry>
				<cylinder radius="0.2" length="0.1"/>
			</geometry>
		</collision>
		<inertial>
			<origin xyz="0. 0. 0."/>
			<mass value="2."/>
			<inertia ixx="0.0020833333" ixy="0." ixz="0." 
					  iyy="0.0070833333" iyz="0."
					  izz="0.0083333333"/>
		</inertial>
	</link>

	<link name="FLwheel_link1">
		<visual>
			<geometry>
				<cylinder radius="0.2" length="0.1"/>
			</geometry>
			<material name="Black">
				<color rgba="0. 0. 0. 1."/>
			</material>
		</visual>
		<collision>
			<geometry>
				<cylinder radius="0.2" length="0.1"/>
			</geometry>
		</collision>		
		<inertial>
			<origin xyz="0. 0. 0."/>
			<mass value="0.500"/>
			<inertia ixx="0.0020833333" ixy="0." ixz="0." 
					  iyy="0.0070833333" iyz="0."
					  izz="0.0083333333"/>
		</inertial>
	</link>
	<link name="FLwheel_link2">
		<visual>
			<geometry>
				<cylinder radius="0.2" length="0.1"/>
			</geometry>
			<material name="Black">
				<color rgba="0. 0. 0. 1."/>
			</material>
		</visual>
		<collision>
			<geometry>
				<cylinder radius="0.2" length="0.1"/>
			</geometry>
		</collision>		
		<inertial>
			<origin xyz="0. 0. 0."/>
			<mass value="0.500"/>
			<inertia ixx="0.0020833333" ixy="0." ixz="0." 
					  iyy="0.0070833333" iyz="0."
					  izz="0.0083333333"/>
		</inertial>
	</link>

	<link name="RRwheel_link1">
		<visual>
			<geometry>
				<cylinder radius="0.2" length="0.1"/>
			</geometry>
			<material name="Black">
				<color rgba="0. 0. 0. 1."/>
			</material>
		</visual>
		<collision>
			<geometry>
				<cylinder radius="0.2" length="0.1"/>
			</geometry>
		</collision>
		<inertial>
			<origin xyz="0. 0. 0."/>
			<mass value="0.500"/>
			<inertia ixx="0.0020833333" ixy="0." ixz="0." 
					  iyy="0.0070833333" iyz="0."
					  izz="0.0083333333"/>
		</inertial>
	</link>
	<link name="RRwheel_link2">
		<visual>
			<geometry>
				<cylinder radius="0.2" length="0.1"/>
			</geometry>
			<material name="Black">
				<color rgba="0. 0. 0. 1."/>
			</material>
		</visual>
		<collision>
			<geometry>
				<cylinder radius="0.2" length="0.1"/>
			</geometry>
		</collision>
		<inertial>
			<origin xyz="0. 0. 0."/>
			<mass value="0.500"/>
			<inertia ixx="0.0020833333" ixy="0." ixz="0." 
					  iyy="0.0070833333" iyz="0."
					  izz="0.0083333333"/>
		</inertial>
	</link>

	<link name="RLwheel_link1">
		<visual>
			<geometry>
				<cylinder radius="0.2" length="0.1"/>
			</geometry>
			<material name="Black">
				<color rgba="0. 0. 0. 1."/>
			</material>
		</visual>
		<collision>
			<geometry>
				<cylinder radius="0.2" length="0.1"/>
			</geometry>
		</collision>
		<inertial>
			<origin xyz="0. 0. 0."/>
			<mass value="0.5"/>
			<inertia ixx="0.0020833333" ixy="0." ixz="0." 
					  iyy="0.0070833333" iyz="0."
					  izz="0.0083333333"/>
		</inertial>
	</link>
	<link name="RLwheel_link2">
		<visual>
			<geometry>
				<cylinder radius="0.2" length="0.1"/>
			</geometry>
			<material name="Black">
				<color rgba="0. 0. 0. 1."/>
			</material>
		</visual>
		<collision>
			<geometry>
				<cylinder radius="0.2" length="0.1"/>
			</geometry>
		</collision>
		<inertial>
			<origin xyz="0. 0. 0."/>
			<mass value="0.5"/>
			<inertia ixx="0.0020833333" ixy="0." ixz="0." 
					  iyy="0.0070833333" iyz="0."
					  izz="0.0083333333"/>
		</inertial>
	</link>
	
	<joint name="base_joint" type="fixed">
		<origin xyz="0. 0. 0.3" rpy="0. 0. 0."/>
		<parent link="base_link"/>
		<child link="body_link"/>

		<calibration rising="0."/>
		<dynamics damping="0." friction="0."/>
	 </joint>

 	<joint name="FRwheel_joint1" type="revolute">
 		<limit lower="-1.57" upper="1.57" effort="1." velocity="5."/>
		<origin xyz="0.375 0.375 0." rpy="-1.57 0. 0."/>
		<axis xyz="0. 1. 0."/>
		<parent link="body_link"/>
		<child link="FRwheel_link1"/>

		<calibration rising="0."/>
		<dynamics damping="0." friction="0."/>
	 </joint>

 	<joint name="FRwheel_joint2" type="continuous">
		<origin xyz="0. 0. 0." rpy="0. 0. 0."/>
		<axis xyz="0. 0. 1."/>
		<parent link="FRwheel_link1"/>
		<child link="FRwheel_link2"/>

		<calibration rising="0."/>
		<dynamics damping="0." friction="0."/>
	 </joint>

  	<joint name="FLwheel_joint1" type="revolute">
  		<limit lower="-1.57" upper="1.57" effort="1." velocity="5."/>
		<origin xyz="0.375 -0.375 0." rpy="-1.57 0. 0."/>
		<axis xyz="0. 1. 0."/>
		<parent link="body_link"/>
		<child link="FLwheel_link1"/>

		<calibration rising="0."/>
		<dynamics damping="0." friction="0."/>
	 </joint>

  	<joint name="FLwheel_joint2" type="continuous">
		<origin xyz="0. 0. 0." rpy="0. 0. 0."/>
		<axis xyz="0. 0. 1."/>
		<parent link="FLwheel_link1"/>
		<child link="FLwheel_link2"/>

		<calibration rising="0."/>
		<dynamics damping="0." friction="0."/>
	 </joint>

 	<joint name="RRwheel_joint1" type="revolute">
 		<limit lower="-1.57" upper="1.57" effort="1." velocity="5."/>
		<origin xyz="-0.375 0.375 0." rpy="-1.57 0. 0."/>
		<axis xyz="0. 1. 0."/>
		<parent link="body_link"/>
		<child link="RRwheel_link1"/>

		<calibration rising="0."/>
		<dynamics damping="0." friction="0."/>
	 </joint>

 	<joint name="RRwheel_joint2" type="continuous">
		<origin xyz="0. 0. 0." rpy="0. 0. 0."/>
		<axis xyz="0. 0. 1."/>
		<parent link="RRwheel_link1"/>
		<child link="RRwheel_link2"/>

		<calibration rising="0."/>
		<dynamics damping="0." friction="0."/>
	 </joint>

  	<joint name="RLwheel_joint1" type="revolute">
  		<limit lower="-1.57" upper="1.57" effort="1." velocity="5."/>
		<origin xyz="-0.375 -0.375 0." rpy="-1.57 0. 0."/>
		<axis xyz="0. 1. 0."/>
		<parent link="body_link"/>
		<child link="RLwheel_link1"/>

		<calibration rising="0."/>
		<dynamics damping="0." friction="0."/>
	 </joint>

   	<joint name="RLwheel_joint2" type="continuous">
		<origin xyz="0. 0. 0." rpy="0. 0. 0."/>
		<axis xyz="0. 0. 1."/>
		<parent link="RLwheel_link1"/>
		<child link="RLwheel_link2"/>

		<calibration rising="0."/>
		<dynamics damping="0." friction="0."/>
	 </joint>

 	<transmission name="FRwheel_trans1">
		<type>transmission_interface/SimpleTransmission</type>
		<joint name="FRwheel_joint1">
			<hardwareInterface>hardware_interface/PositionJointInterface</hardwareInterface>
		</joint>
		<actuator name="FRwheel_motor1">
			<mechanicalReduction>1</mechanicalReduction>
			<hardwareInterface>hardware_interface/PositionJointInterface</hardwareInterface>
		</actuator>
	</transmission>

	<transmission name="RRwheel_trans1">
		<type>transmission_interface/SimpleTransmission</type>
		<joint name="RRwheel_joint1">
			<hardwareInterface>hardware_interface/PositionJointInterface</hardwareInterface>
		</joint>
		<actuator name="RRwheel_motor1">
			<mechanicalReduction>1</mechanicalReduction>
			<hardwareInterface>hardware_interface/PositionJointInterface</hardwareInterface>
		</actuator>
	</transmission>

	<transmission name="FLwheel_trans1">
		<type>transmission_interface/SimpleTransmission</type>
		<joint name="FLwheel_joint1">
			<hardwareInterface>hardware_interface/PositionJointInterface</hardwareInterface>
		</joint>
		<actuator name="FLwheel_motor1">
			<mechanicalReduction>1</mechanicalReduction>
			<hardwareInterface>hardware_interface/PositionJointInterface</hardwareInterface>
		</actuator>
	</transmission>	

	<transmission name="RLwheel_trans1">
		<type>transmission_interface/SimpleTransmission</type>
		<joint name="RLwheel_joint1">
			<hardwareInterface>hardware_interface/PositionJointInterface</hardwareInterface>
		</joint>
		<actuator name="RLwheel_motor1">
			<mechanicalReduction>1</mechanicalReduction>
			<hardwareInterface>hardware_interface/PositionJointInterface</hardwareInterface>
		</actuator>
	</transmission>

	<transmission name="FRwheel_trans2">
		<type>transmission_interface/SimpleTransmission</type>
		<joint name="FRwheel_joint2">
			<hardwareInterface>hardware_interface/VelocityJointInterface</hardwareInterface>
		</joint>
		<actuator name="FRwheel_motor2">
			<mechanicalReduction>1</mechanicalReduction>
			<hardwareInterface>hardware_interface/VelocityJointInterface</hardwareInterface>
		</actuator>
	</transmission>

	<transmission name="RRwheel_trans2">
		<type>transmission_interface/SimpleTransmission</type>
		<joint name="RRwheel_joint2">
			<hardwareInterface>hardware_interface/VelocityJointInterface</hardwareInterface>
		</joint>
		<actuator name="RRwheel_motor2">
			<mechanicalReduction>1</mechanicalReduction>
			<hardwareInterface>hardware_interface/VelocityJointInterface</hardwareInterface>
		</actuator>
	</transmission>

	<transmission name="FLwheel_trans2">
		<type>transmission_interface/SimpleTransmission</type>
		<joint name="FLwheel_joint2">
			<hardwareInterface>hardware_interface/VelocityJointInterface</hardwareInterface>
		</joint>
		<actuator name="FLwheel_motor2">
			<mechanicalReduction>1</mechanicalReduction>
			<hardwareInterface>hardware_interface/VelocityJointInterface</hardwareInterface>
		</actuator>
	</transmission>	

	<transmission name="RLwheel_trans2">
		<type>transmission_interface/SimpleTransmission</type>
		<joint name="RLwheel_joint2">
			<hardwareInterface>hardware_interface/VelocityJointInterface</hardwareInterface>
		</joint>
		<actuator name="RLwheel_motor2">
			<mechanicalReduction>1</mechanicalReduction>
			<hardwareInterface>hardware_interface/VelocityJointInterface</hardwareInterface>
		</actuator>
	</transmission> 
	
	<gazebo>
		<plugin name="gazebo_ros_control" filename="libgazebo_ros_control.so">
			<controlPeriod>0.001</controlPeriod>
			<legacyModeNS>true</legacyModeNS>
			<robotParam>/robot_description</robotParam>
			<robotNamespace>/omnidirectional_four_wheeled_robot</robotNamespace>
			<robotSimType>gazebo_ros_control/DefaultRobotHWSim</robotSimType>
		</plugin>
	</gazebo>

	<gazebo reference="base_link">
		<selfCollide>false</selfCollide>
		<mu1 value="0.05" />
		<mu2 value="0.05" />
	</gazebo>

	<gazebo reference="FRwheel_link1">
		<selfCollide>false</selfCollide>
		<mu1 value="0.05" />
		<mu2 value="0.05" />
	</gazebo>

	<gazebo reference="FRwheel_link2">
		<selfCollide>false</selfCollide>
		<mu1 value="0.8" />
		<mu2 value="0.8" />
	</gazebo>

	<gazebo reference="RRwheel_link1">
		<selfCollide>false</selfCollide>
		<mu1 value="0.05" />
		<mu2 value="0.05" />
	</gazebo>

	<gazebo reference="RRwheel_link2">
		<selfCollide>false</selfCollide>
		<mu1 value="0.8" />
		<mu2 value="0.8" />
	</gazebo>

	<gazebo reference="FLwheel_link1">
		<selfCollide>false</selfCollide>
		<mu1 value="0.05" />
		<mu2 value="0.05" />
	</gazebo>

	<gazebo reference="FLwheel_link2">
		<selfCollide>false</selfCollide>
		<mu1 value="0.8" />
		<mu2 value="0.8" />
	</gazebo> 

	<gazebo reference="RLwheel_link1">
		<selfCollide>false</selfCollide>
		<mu1 value="0.05" />
		<mu2 value="0.05" />
	</gazebo>

	<gazebo reference="RLwheel_link2">
		<selfCollide>false</selfCollide>
		<mu1 value="0.8" />
		<mu2 value="0.8" />
	</gazebo>
</robot>