<?xml version="1.0"?>
<robot name="omnidirectional_four-wheeled_robot">
	<link name="base_link"/>
	<link name="body_link">
		<visual>
			<geometry>
				<box size="0.750 0.750 0.250"/>
			</geometry>
			<material name="White">
				<color rgba="1. 1. 1. 1."/>
			</material>
		</visual>

		<collision>
			<geometry>
				<box size="0.750 0.750 0.250"/>
			</geometry>
		</collision>

		<inertial>
			<origin xyz="0 0 0"/>
			<mass value="0.500"/>
			<inertia ixx="0.0020833333" ixy="0" ixz="0" 
					  iyy="0.0070833333" iyz="0"
					  izz="0.0083333333"/>
		</inertial>
	</link>

	<link name="rightFrontWheel_link1">
		<visual>
			<geometry>
				<cylinder radius="0.2" length="0.1"/>
			</geometry>
			<material name="Black">
				<color rgba="0. 0. 0. 1."/>
			</material>
		</visual>
		<collision>
			<geometry>
				<cylinder radius="0.2" length="0.1"/>
			</geometry>
		</collision>
		<inertial>
			<origin xyz="0. 0. 0."/>
			<mass value="2."/>
			<inertia ixx="0.0020833333" ixy="0." ixz="0." 
					  iyy="0.0070833333" iyz="0."
					  izz="0.0083333333"/>
		</inertial>
	</link>

	<link name="rightFrontWheel_link2">
		<visual>
			<geometry>
				<cylinder radius="0.2" length="0.1"/>
			</geometry>
			<material name="Black">
				<color rgba="0. 0. 0. 1."/>
			</material>
		</visual>
		<collision>
			<geometry>
				<cylinder radius="0.2" length="0.1"/>
			</geometry>
		</collision>
		<inertial>
			<origin xyz="0. 0. 0."/>
			<mass value="2."/>
			<inertia ixx="0.0020833333" ixy="0." ixz="0." 
					  iyy="0.0070833333" iyz="0."
					  izz="0.0083333333"/>
		</inertial>
	</link>

	<link name="leftFrontWheel_link1">
		<visual>
			<geometry>
				<cylinder radius="0.2" length="0.1"/>
			</geometry>
			<material name="Black">
				<color rgba="0. 0. 0. 1."/>
			</material>
		</visual>
		<collision>
			<geometry>
				<cylinder radius="0.2" length="0.1"/>
			</geometry>
		</collision>		
		<inertial>
			<origin xyz="0. 0. 0."/>
			<mass value="0.500"/>
			<inertia ixx="0.0020833333" ixy="0." ixz="0." 
					  iyy="0.0070833333" iyz="0."
					  izz="0.0083333333"/>
		</inertial>
	</link>
	<link name="leftFrontWheel_link2">
		<visual>
			<geometry>
				<cylinder radius="0.2" length="0.1"/>
			</geometry>
			<material name="Black">
				<color rgba="0. 0. 0. 1."/>
			</material>
		</visual>
		<collision>
			<geometry>
				<cylinder radius="0.2" length="0.1"/>
			</geometry>
		</collision>		
		<inertial>
			<origin xyz="0. 0. 0."/>
			<mass value="0.500"/>
			<inertia ixx="0.0020833333" ixy="0." ixz="0." 
					  iyy="0.0070833333" iyz="0."
					  izz="0.0083333333"/>
		</inertial>
	</link>

	<link name="rightBackWheel_link1">
		<visual>
			<geometry>
				<cylinder radius="0.2" length="0.1"/>
			</geometry>
			<material name="Black">
				<color rgba="0. 0. 0. 1."/>
			</material>
		</visual>
		<collision>
			<geometry>
				<cylinder radius="0.2" length="0.1"/>
			</geometry>
		</collision>
		<inertial>
			<origin xyz="0. 0. 0."/>
			<mass value="0.500"/>
			<inertia ixx="0.0020833333" ixy="0." ixz="0." 
					  iyy="0.0070833333" iyz="0."
					  izz="0.0083333333"/>
		</inertial>
	</link>
	<link name="rightBackWheel_link2">
		<visual>
			<geometry>
				<cylinder radius="0.2" length="0.1"/>
			</geometry>
			<material name="Black">
				<color rgba="0. 0. 0. 1."/>
			</material>
		</visual>
		<collision>
			<geometry>
				<cylinder radius="0.2" length="0.1"/>
			</geometry>
		</collision>
		<inertial>
			<origin xyz="0. 0. 0."/>
			<mass value="0.500"/>
			<inertia ixx="0.0020833333" ixy="0." ixz="0." 
					  iyy="0.0070833333" iyz="0."
					  izz="0.0083333333"/>
		</inertial>
	</link>

	<link name="leftBackWheel_link1">
		<visual>
			<geometry>
				<cylinder radius="0.2" length="0.1"/>
			</geometry>
			<material name="Black">
				<color rgba="0. 0. 0. 1."/>
			</material>
		</visual>
		<collision>
			<geometry>
				<cylinder radius="0.2" length="0.1"/>
			</geometry>
		</collision>
		<inertial>
			<origin xyz="0. 0. 0."/>
			<mass value="0.5"/>
			<inertia ixx="0.0020833333" ixy="0." ixz="0." 
					  iyy="0.0070833333" iyz="0."
					  izz="0.0083333333"/>
		</inertial>
	</link>
	<link name="leftBackWheel_link2">
		<visual>
			<geometry>
				<cylinder radius="0.2" length="0.1"/>
			</geometry>
			<material name="Black">
				<color rgba="0. 0. 0. 1."/>
			</material>
		</visual>
		<collision>
			<geometry>
				<cylinder radius="0.2" length="0.1"/>
			</geometry>
		</collision>
		<inertial>
			<origin xyz="0. 0. 0."/>
			<mass value="0.5"/>
			<inertia ixx="0.0020833333" ixy="0." ixz="0." 
					  iyy="0.0070833333" iyz="0."
					  izz="0.0083333333"/>
		</inertial>
	</link>
	
	<joint name="base_joint" type="fixed">
		<origin xyz="0. 0. 0.3" rpy="0. 0. 0."/>
		<parent link="base_link"/>
		<child link="body_link"/>

		<calibration rising="0."/>
		<dynamics damping="0." friction="0."/>
	 </joint>

 	<joint name="rightFrontWheel_joint1" type="revolute">
 		<limit lower="-1.57" upper="1.57" effort="1." velocity="5."/>
		<origin xyz="0.375 0.375 0." rpy="-1.57 0. 0."/>
		<axis xyz="0. 1. 0."/>
		<parent link="body_link"/>
		<child link="rightFrontWheel_link1"/>

		<calibration rising="0."/>
		<dynamics damping="0." friction="0."/>
	 </joint>

 	<joint name="rightFrontWheel_joint2" type="continuous">
		<origin xyz="0. 0. 0." rpy="0. 0. 0."/>
		<axis xyz="0. 0. 1."/>
		<parent link="rightFrontWheel_link1"/>
		<child link="rightFrontWheel_link2"/>

		<calibration rising="0."/>
		<dynamics damping="0." friction="0."/>
	 </joint>

  	<joint name="leftFrontWheel_joint1" type="revolute">
  		<limit lower="-1.57" upper="1.57" effort="1." velocity="5."/>
		<origin xyz="0.375 -0.375 0." rpy="-1.57 0. 0."/>
		<axis xyz="0. 1. 0."/>
		<parent link="body_link"/>
		<child link="leftFrontWheel_link1"/>

		<calibration rising="0."/>
		<dynamics damping="0." friction="0."/>
	 </joint>

  	<joint name="leftFrontWheel_joint2" type="continuous">
		<origin xyz="0. 0. 0." rpy="0. 0. 0."/>
		<axis xyz="0. 0. 1."/>
		<parent link="leftFrontWheel_link1"/>
		<child link="leftFrontWheel_link2"/>

		<calibration rising="0."/>
		<dynamics damping="0." friction="0."/>
	 </joint>

 	<joint name="rightBackWheel_joint1" type="revolute">
 		<limit lower="-1.57" upper="1.57" effort="1." velocity="5."/>
		<origin xyz="-0.375 0.375 0." rpy="-1.57 0. 0."/>
		<axis xyz="0. 1. 0."/>
		<parent link="body_link"/>
		<child link="rightBackWheel_link1"/>

		<calibration rising="0."/>
		<dynamics damping="0." friction="0."/>
	 </joint>

 	<joint name="rightBackWheel_joint2" type="continuous">
		<origin xyz="0. 0. 0." rpy="0. 0. 0."/>
		<axis xyz="0. 0. 1."/>
		<parent link="rightBackWheel_link1"/>
		<child link="rightBackWheel_link2"/>

		<calibration rising="0."/>
		<dynamics damping="0." friction="0."/>
	 </joint>

  	<joint name="leftBackWheel_joint1" type="revolute">
  		<limit lower="-1.57" upper="1.57" effort="1." velocity="5."/>
		<origin xyz="-0.375 -0.375 0." rpy="-1.57 0. 0."/>
		<axis xyz="0. 1. 0."/>
		<parent link="body_link"/>
		<child link="leftBackWheel_link1"/>

		<calibration rising="0."/>
		<dynamics damping="0." friction="0."/>
	 </joint>

   	<joint name="leftBackWheel_joint2" type="continuous">
		<origin xyz="0. 0. 0." rpy="0. 0. 0."/>
		<axis xyz="0. 0. 1."/>
		<parent link="leftBackWheel_link1"/>
		<child link="leftBackWheel_link2"/>

		<calibration rising="0."/>
		<dynamics damping="0." friction="0."/>
	 </joint>

 	<transmission name="rightFrontWheel_trans1">
		<type>transmission_interface/SimpleTransmission</type>
		<joint name="rightFrontWheel_joint1">
			<hardwareInterface>hardware_interface/EffortJointInterface</hardwareInterface>
		</joint>
		<actuator name="rightFrontWheel_motor1">
			<mechanicalReduction>1</mechanicalReduction>
			<hardwareInterface>hardware_interface/EffortJointInterface</hardwareInterface>
		</actuator>
	</transmission>

	<transmission name="rightBackWheel_trans1">
		<type>transmission_interface/SimpleTransmission</type>
		<joint name="rightBackWheel_joint1">
			<hardwareInterface>hardware_interface/EffortJointInterface</hardwareInterface>
		</joint>
		<actuator name="rightBackWheel_motor1">
			<mechanicalReduction>1</mechanicalReduction>
			<hardwareInterface>hardware_interface/EffortJointInterface</hardwareInterface>
		</actuator>
	</transmission>

	<transmission name="leftFrontWheel_trans1">
		<type>transmission_interface/SimpleTransmission</type>
		<joint name="leftFrontWheel_joint1">
			<hardwareInterface>hardware_interface/EffortJointInterface</hardwareInterface>
		</joint>
		<actuator name="leftFrontWheel_motor1">
			<mechanicalReduction>1</mechanicalReduction>
			<hardwareInterface>hardware_interface/EffortJointInterface</hardwareInterface>
		</actuator>
	</transmission>	

	<transmission name="leftBackWheel_trans1">
		<type>transmission_interface/SimpleTransmission</type>
		<joint name="leftBackWheel_joint1">
			<hardwareInterface>hardware_interface/EffortJointInterface</hardwareInterface>
		</joint>
		<actuator name="leftBackWheel_motor1">
			<mechanicalReduction>1</mechanicalReduction>
			<hardwareInterface>hardware_interface/EffortJointInterface</hardwareInterface>
		</actuator>
	</transmission>

	<transmission name="rightFrontWheel_trans2">
		<type>transmission_interface/SimpleTransmission</type>
		<joint name="rightFrontWheel_joint2">
			<hardwareInterface>hardware_interface/EffortJointInterface</hardwareInterface>
		</joint>
		<actuator name="rightFrontWheel_motor2">
			<mechanicalReduction>1</mechanicalReduction>
			<hardwareInterface>hardware_interface/EffortJointInterface</hardwareInterface>
		</actuator>
	</transmission>

	<transmission name="rightBackWheel_trans2">
		<type>transmission_interface/SimpleTransmission</type>
		<joint name="rightBackWheel_joint2">
			<hardwareInterface>hardware_interface/EffortJointInterface</hardwareInterface>
		</joint>
		<actuator name="rightBackWheel_motor2">
			<mechanicalReduction>1</mechanicalReduction>
			<hardwareInterface>hardware_interface/EffortJointInterface</hardwareInterface>
		</actuator>
	</transmission>

	<transmission name="leftFrontWheel_trans2">
		<type>transmission_interface/SimpleTransmission</type>
		<joint name="leftFrontWheel_joint2">
			<hardwareInterface>hardware_interface/EffortJointInterface</hardwareInterface>
		</joint>
		<actuator name="leftFrontWheel_motor2">
			<mechanicalReduction>1</mechanicalReduction>
			<hardwareInterface>hardware_interface/EffortJointInterface</hardwareInterface>
		</actuator>
	</transmission>	

	<transmission name="leftBackWheel_trans2">
		<type>transmission_interface/SimpleTransmission</type>
		<joint name="leftBackWheel_joint2">
			<hardwareInterface>hardware_interface/EffortJointInterface</hardwareInterface>
		</joint>
		<actuator name="leftBackWheel_motor2">
			<mechanicalReduction>1</mechanicalReduction>
			<hardwareInterface>hardware_interface/EffortJointInterface</hardwareInterface>
		</actuator>
	</transmission> 
	
	<gazebo>
		<plugin name="gazebo_ros_control" filename="libgazebo_ros_control.so">
			<robotNamespace>/omnidirectional_four-wheeled_robot</robotNamespace>
			<robotSimType>gazebo_ros_control/DefaultRobotHWSim</robotSimType>
		</plugin>
	</gazebo>

	<gazebo reference="base_link">
		<selfCollide>false</selfCollide>
		<mu1 value="0.05" />
		<mu2 value="0.05" />
	</gazebo>

	<gazebo reference="leftBackWheel_link1">
		<selfCollide>false</selfCollide>
		<mu1 value="0.05" />
		<mu2 value="0.05" />
	</gazebo>

	<gazebo reference="leftBackWheel_link2">
		<selfCollide>false</selfCollide>
		<mu1 value="0.8" />
		<mu2 value="0.8" />
	</gazebo>

	<gazebo reference="leftBackWheel_link1">
		<selfCollide>false</selfCollide>
		<mu1 value="0.05" />
		<mu2 value="0.05" />
	</gazebo>

	<gazebo reference="leftBackWheel_link2">
		<selfCollide>false</selfCollide>
		<mu1 value="0.8" />
		<mu2 value="0.8" />
	</gazebo>

	<gazebo reference="leftFrontWheel_link1">
		<selfCollide>false</selfCollide>
		<mu1 value="0.05" />
		<mu2 value="0.05" />
	</gazebo>

	<gazebo reference="leftFrontWheel_link2">
		<selfCollide>false</selfCollide>
		<mu1 value="0.8" />
		<mu2 value="0.8" />
	</gazebo>

	<gazebo reference="leftFrontWheel_link1">
		<selfCollide>false</selfCollide>
		<mu1 value="0.05" />
		<mu2 value="0.05" />
	</gazebo>

	<gazebo reference="leftFrontWheel_link2">
		<selfCollide>false</selfCollide>
		<mu1 value="0.8" />
		<mu2 value="0.8" />
	</gazebo> 

</robot>